Failure in python_multiple_errors.py:

  The CHECK on line 7 wants:
    eins

  which failed to match line stdout:2:
    one

  Context:
    foo
    one <= does not match 'eins'
    two <= does not match 'zwei'
    bar

  when running command:
    /usr/bin/python python_multiple_errors.py
