Failure in python_out_vs_err.py:

  The CHECK on line 17 wants:
    things should be cool

  which failed to match line stdout:2:
    now stdout is broken

  additional output on stderr:1:
    something failed

 Context:
    fine so far
    now stdout is broken <= does not match 'things should be cool'
    
  when running command:
    /usr/bin/python python_out_vs_err.py
